WARNING: Retrying (Retry(total=4, connect=None, read=None, redirect=None, status=None)) after connection broken by 'ReadTimeoutError("HTTPSConnectionPool(host='pypi.org', port=443): Read timed out. (read timeout=15)")': /simple/poetry/
Collecting poetry==1.3.2
  Downloading poetry-1.3.2-py3-none-any.whl (218 kB)
     ------------------------------------ 218.9/218.9 kB 196.3 kB/s eta 0:00:00
Collecting cachecontrol[filecache]<0.13.0,>=0.12.9
  Downloading CacheControl-0.12.11-py2.py3-none-any.whl (21 kB)
Collecting cleo<3.0.0,>=2.0.0
  WARNING: Retrying (Retry(total=4, connect=None, read=None, redirect=None, status=None)) after connection broken by 'ReadTimeoutError("HTTPSConnectionPool(host='files.pythonhosted.org', port=443): Read timed out. (read timeout=15)")': /packages/b1/ae/0329af2a4c22836010c43760233a181a314853a97e0f2b53b02825c4c9b7/cleo-2.0.1-py3-none-any.whl
  Downloading cleo-2.0.1-py3-none-any.whl (77 kB)
     -------------------------------------- 77.3/77.3 kB 536.3 kB/s eta 0:00:00
Collecting crashtest<0.5.0,>=0.4.1
  Downloading crashtest-0.4.1-py3-none-any.whl (7.6 kB)
Collecting dulwich<0.21.0,>=0.20.46
  Downloading dulwich-0.20.50-cp311-cp311-win_amd64.whl (472 kB)
     ------------------------------------ 472.4/472.4 kB 261.7 kB/s eta 0:00:00
Collecting filelock<4.0.0,>=3.8.0
  Downloading filelock-3.9.0-py3-none-any.whl (9.7 kB)
Collecting html5lib<2.0,>=1.0
  Downloading html5lib-1.1-py2.py3-none-any.whl (112 kB)
     -------------------------------------- 112.2/112.2 kB 6.8 MB/s eta 0:00:00
Collecting jsonschema<5.0.0,>=4.10.0
  Downloading jsonschema-4.17.3-py3-none-any.whl (90 kB)
                                              0.0/90.4 kB ? eta -:--:--
ERROR: Exception:
Traceback (most recent call last):
  File "C:\Users\sahar\AppData\Roaming\pypoetry\venv\Lib\site-packages\pip\_vendor\urllib3\response.py", line 437, in _error_catcher
    yield
  File "C:\Users\sahar\AppData\Roaming\pypoetry\venv\Lib\site-packages\pip\_vendor\urllib3\response.py", line 560, in read
    data = self._fp_read(amt) if not fp_closed else b""
           ^^^^^^^^^^^^^^^^^^
  File "C:\Users\sahar\AppData\Roaming\pypoetry\venv\Lib\site-packages\pip\_vendor\urllib3\response.py", line 526, in _fp_read
    return self._fp.read(amt) if amt is not None else self._fp.read()
           ^^^^^^^^^^^^^^^^^^
  File "C:\Users\sahar\AppData\Roaming\pypoetry\venv\Lib\site-packages\pip\_vendor\cachecontrol\filewrapper.py", line 90, in read
    data = self.__fp.read(amt)
           ^^^^^^^^^^^^^^^^^^^
  File "C:\Users\sahar\AppData\Local\Programs\Python\Python311\Lib\http\client.py", line 465, in read
    s = self.fp.read(amt)
        ^^^^^^^^^^^^^^^^^
  File "C:\Users\sahar\AppData\Local\Programs\Python\Python311\Lib\socket.py", line 706, in readinto
    return self._sock.recv_into(b)
           ^^^^^^^^^^^^^^^^^^^^^^^
  File "C:\Users\sahar\AppData\Local\Programs\Python\Python311\Lib\ssl.py", line 1278, in recv_into
    return self.read(nbytes, buffer)
           ^^^^^^^^^^^^^^^^^^^^^^^^^
  File "C:\Users\sahar\AppData\Local\Programs\Python\Python311\Lib\ssl.py", line 1134, in read
    return self._sslobj.read(len, buffer)
           ^^^^^^^^^^^^^^^^^^^^^^^^^^^^^^
TimeoutError: The read operation timed out

During handling of the above exception, another exception occurred:

Traceback (most recent call last):
  File "C:\Users\sahar\AppData\Roaming\pypoetry\venv\Lib\site-packages\pip\_internal\cli\base_command.py", line 160, in exc_logging_wrapper
    status = run_func(*args)
             ^^^^^^^^^^^^^^^
  File "C:\Users\sahar\AppData\Roaming\pypoetry\venv\Lib\site-packages\pip\_internal\cli\req_command.py", line 247, in wrapper
    return func(self, options, args)
           ^^^^^^^^^^^^^^^^^^^^^^^^^
  File "C:\Users\sahar\AppData\Roaming\pypoetry\venv\Lib\site-packages\pip\_internal\commands\install.py", line 400, in run
    requirement_set = resolver.resolve(
                      ^^^^^^^^^^^^^^^^^
  File "C:\Users\sahar\AppData\Roaming\pypoetry\venv\Lib\site-packages\pip\_internal\resolution\resolvelib\resolver.py", line 92, in resolve
    result = self._result = resolver.resolve(
                            ^^^^^^^^^^^^^^^^^
  File "C:\Users\sahar\AppData\Roaming\pypoetry\venv\Lib\site-packages\pip\_vendor\resolvelib\resolvers.py", line 481, in resolve
    state = resolution.resolve(requirements, max_rounds=max_rounds)
            ^^^^^^^^^^^^^^^^^^^^^^^^^^^^^^^^^^^^^^^^^^^^^^^^^^^^^^^
  File "C:\Users\sahar\AppData\Roaming\pypoetry\venv\Lib\site-packages\pip\_vendor\resolvelib\resolvers.py", line 373, in resolve
    failure_causes = self._attempt_to_pin_criterion(name)
                     ^^^^^^^^^^^^^^^^^^^^^^^^^^^^^^^^^^^^
  File "C:\Users\sahar\AppData\Roaming\pypoetry\venv\Lib\site-packages\pip\_vendor\resolvelib\resolvers.py", line 213, in _attempt_to_pin_criterion
    criteria = self._get_updated_criteria(candidate)
               ^^^^^^^^^^^^^^^^^^^^^^^^^^^^^^^^^^^^^
  File "C:\Users\sahar\AppData\Roaming\pypoetry\venv\Lib\site-packages\pip\_vendor\resolvelib\resolvers.py", line 204, in _get_updated_criteria
    self._add_to_criteria(criteria, requirement, parent=candidate)
  File "C:\Users\sahar\AppData\Roaming\pypoetry\venv\Lib\site-packages\pip\_vendor\resolvelib\resolvers.py", line 172, in _add_to_criteria
    if not criterion.candidates:
  File "C:\Users\sahar\AppData\Roaming\pypoetry\venv\Lib\site-packages\pip\_vendor\resolvelib\structs.py", line 151, in __bool__
    return bool(self._sequence)
           ^^^^^^^^^^^^^^^^^^^^
  File "C:\Users\sahar\AppData\Roaming\pypoetry\venv\Lib\site-packages\pip\_internal\resolution\resolvelib\found_candidates.py", line 155, in __bool__
    return any(self)
           ^^^^^^^^^
  File "C:\Users\sahar\AppData\Roaming\pypoetry\venv\Lib\site-packages\pip\_internal\resolution\resolvelib\found_candidates.py", line 143, in <genexpr>
    return (c for c in iterator if id(c) not in self._incompatible_ids)
           ^^^^^^^^^^^^^^^^^^^^^^^^^^^^^^^^^^^^^^^^^^^^^^^^^^^^^^^^^^^^
  File "C:\Users\sahar\AppData\Roaming\pypoetry\venv\Lib\site-packages\pip\_internal\resolution\resolvelib\found_candidates.py", line 47, in _iter_built
    candidate = func()
                ^^^^^^
  File "C:\Users\sahar\AppData\Roaming\pypoetry\venv\Lib\site-packages\pip\_internal\resolution\resolvelib\factory.py", line 206, in _make_candidate_from_link
    self._link_candidate_cache[link] = LinkCandidate(
                                       ^^^^^^^^^^^^^^
  File "C:\Users\sahar\AppData\Roaming\pypoetry\venv\Lib\site-packages\pip\_internal\resolution\resolvelib\candidates.py", line 297, in __init__
    super().__init__(
  File "C:\Users\sahar\AppData\Roaming\pypoetry\venv\Lib\site-packages\pip\_internal\resolution\resolvelib\candidates.py", line 162, in __init__
    self.dist = self._prepare()
                ^^^^^^^^^^^^^^^
  File "C:\Users\sahar\AppData\Roaming\pypoetry\venv\Lib\site-packages\pip\_internal\resolution\resolvelib\candidates.py", line 231, in _prepare
    dist = self._prepare_distribution()
           ^^^^^^^^^^^^^^^^^^^^^^^^^^^^
  File "C:\Users\sahar\AppData\Roaming\pypoetry\venv\Lib\site-packages\pip\_internal\resolution\resolvelib\candidates.py", line 308, in _prepare_distribution
    return preparer.prepare_linked_requirement(self._ireq, parallel_builds=True)
           ^^^^^^^^^^^^^^^^^^^^^^^^^^^^^^^^^^^^^^^^^^^^^^^^^^^^^^^^^^^^^^^^^^^^^
  File "C:\Users\sahar\AppData\Roaming\pypoetry\venv\Lib\site-packages\pip\_internal\operations\prepare.py", line 491, in prepare_linked_requirement
    return self._prepare_linked_requirement(req, parallel_builds)
           ^^^^^^^^^^^^^^^^^^^^^^^^^^^^^^^^^^^^^^^^^^^^^^^^^^^^^^
  File "C:\Users\sahar\AppData\Roaming\pypoetry\venv\Lib\site-packages\pip\_internal\operations\prepare.py", line 536, in _prepare_linked_requirement
    local_file = unpack_url(
                 ^^^^^^^^^^^
  File "C:\Users\sahar\AppData\Roaming\pypoetry\venv\Lib\site-packages\pip\_internal\operations\prepare.py", line 166, in unpack_url
    file = get_http_url(
           ^^^^^^^^^^^^^
  File "C:\Users\sahar\AppData\Roaming\pypoetry\venv\Lib\site-packages\pip\_internal\operations\prepare.py", line 107, in get_http_url
    from_path, content_type = download(link, temp_dir.path)
                              ^^^^^^^^^^^^^^^^^^^^^^^^^^^^^
  File "C:\Users\sahar\AppData\Roaming\pypoetry\venv\Lib\site-packages\pip\_internal\network\download.py", line 147, in __call__
    for chunk in chunks:
  File "C:\Users\sahar\AppData\Roaming\pypoetry\venv\Lib\site-packages\pip\_internal\cli\progress_bars.py", line 53, in _rich_progress_bar
    for chunk in iterable:
  File "C:\Users\sahar\AppData\Roaming\pypoetry\venv\Lib\site-packages\pip\_internal\network\utils.py", line 63, in response_chunks
    for chunk in response.raw.stream(
  File "C:\Users\sahar\AppData\Roaming\pypoetry\venv\Lib\site-packages\pip\_vendor\urllib3\response.py", line 621, in stream
    data = self.read(amt=amt, decode_content=decode_content)
           ^^^^^^^^^^^^^^^^^^^^^^^^^^^^^^^^^^^^^^^^^^^^^^^^^
  File "C:\Users\sahar\AppData\Roaming\pypoetry\venv\Lib\site-packages\pip\_vendor\urllib3\response.py", line 559, in read
    with self._error_catcher():
  File "C:\Users\sahar\AppData\Local\Programs\Python\Python311\Lib\contextlib.py", line 155, in __exit__
    self.gen.throw(typ, value, traceback)
  File "C:\Users\sahar\AppData\Roaming\pypoetry\venv\Lib\site-packages\pip\_vendor\urllib3\response.py", line 442, in _error_catcher
    raise ReadTimeoutError(self._pool, None, "Read timed out.")
pip._vendor.urllib3.exceptions.ReadTimeoutError: HTTPSConnectionPool(host='files.pythonhosted.org', port=443): Read timed out.
WARNING: There was an error checking the latest version of pip.

Traceback:

  File "<stdin>", line 919, in main
  File "<stdin>", line 550, in run
  File "<stdin>", line 572, in install
  File "<stdin>", line 675, in install_poetry
  File "<stdin>", line 367, in pip
  File "<stdin>", line 364, in python
  File "<stdin>", line 357, in run
